<?xml version="1.0" encoding="UTF-8"?>
<testng-results ignored="0" total="8" passed="0" failed="8" skipped="0">
  <reporter-output>
  </reporter-output>
  <suite started-at="2023-01-03T15:32:40 IST" name="Suite" finished-at="2023-01-03T15:35:16 IST" duration-ms="155576">
    <groups>
    </groups>
    <test started-at="2023-01-03T15:32:40 IST" name="Test" finished-at="2023-01-03T15:35:16 IST" duration-ms="155576">
      <class name="sample.DASHBOARD_01">
        <test-method is-config="true" signature="setup()[pri:0, instance:sample.DASHBOARD_01@942a29c]" started-at="2023-01-03T15:32:41 IST" name="setup" finished-at="2023-01-03T15:32:50 IST" duration-ms="9100" status="PASS">
          <reporter-output>
          </reporter-output>
        </test-method> <!-- setup -->
        <test-method is-config="true" signature="login()[pri:0, instance:sample.DASHBOARD_01@942a29c]" started-at="2023-01-03T15:32:53 IST" name="login" finished-at="2023-01-03T15:33:01 IST" duration-ms="7750" status="PASS">
          <reporter-output>
          </reporter-output>
        </test-method> <!-- login -->
        <test-method signature="SUPPORTTICKET(java.lang.String,java.lang.String)[pri:0, instance:sample.DASHBOARD_01@942a29c]" started-at="2023-01-03T15:33:01 IST" name="SUPPORTTICKET" data-provider="OrgData" finished-at="2023-01-03T15:33:15 IST" duration-ms="14148" status="FAIL">
          <params>
            <param index="0">
              <value>
                <![CDATA[wngal46@gmail.com]]>
              </value>
            </param>
            <param index="1">
              <value>
                <![CDATA[SAICHARAN]]>
              </value>
            </param>
          </params>
          <exception class="java.lang.AssertionError">
            <message>
              <![CDATA[expected [ New ticket created successfully ] but found [New ticket created successfully]]]>
            </message>
            <full-stacktrace>
              <![CDATA[java.lang.AssertionError: expected [ New ticket created successfully ] but found [New ticket created successfully]
at org.testng.Assert.fail(Assert.java:99)
at org.testng.Assert.failNotEquals(Assert.java:1037)
at org.testng.Assert.assertEqualsImpl(Assert.java:140)
at org.testng.Assert.assertEquals(Assert.java:122)
at org.testng.Assert.assertEquals(Assert.java:629)
at org.testng.Assert.assertEquals(Assert.java:639)
at PAYTMPE_POR.CREATE_NEW_TICKET_PAGE.User_ticketcreatedsucessfully(CREATE_NEW_TICKET_PAGE.java:43)
at sample.DASHBOARD_01.SUPPORTTICKET(DASHBOARD_01.java:41)
at java.base/jdk.internal.reflect.NativeMethodAccessorImpl.invoke0(Native Method)
at java.base/jdk.internal.reflect.NativeMethodAccessorImpl.invoke(NativeMethodAccessorImpl.java:77)
at java.base/jdk.internal.reflect.DelegatingMethodAccessorImpl.invoke(DelegatingMethodAccessorImpl.java:43)
at java.base/java.lang.reflect.Method.invoke(Method.java:568)
at org.testng.internal.MethodInvocationHelper.invokeMethod(MethodInvocationHelper.java:133)
at org.testng.internal.TestInvoker.invokeMethod(TestInvoker.java:598)
at org.testng.internal.TestInvoker.invokeTestMethod(TestInvoker.java:173)
at org.testng.internal.MethodRunner.runInSequence(MethodRunner.java:46)
at org.testng.internal.TestInvoker$MethodInvocationAgent.invoke(TestInvoker.java:824)
at org.testng.internal.TestInvoker.invokeTestMethods(TestInvoker.java:146)
at org.testng.internal.TestMethodWorker.invokeTestMethods(TestMethodWorker.java:146)
at org.testng.internal.TestMethodWorker.run(TestMethodWorker.java:128)
at java.base/java.util.ArrayList.forEach(ArrayList.java:1511)
at org.testng.TestRunner.privateRun(TestRunner.java:794)
at org.testng.TestRunner.run(TestRunner.java:596)
at org.testng.SuiteRunner.runTest(SuiteRunner.java:377)
at org.testng.SuiteRunner.runSequentially(SuiteRunner.java:371)
at org.testng.SuiteRunner.privateRun(SuiteRunner.java:332)
at org.testng.SuiteRunner.run(SuiteRunner.java:276)
at org.testng.SuiteRunnerWorker.runSuite(SuiteRunnerWorker.java:53)
at org.testng.SuiteRunnerWorker.run(SuiteRunnerWorker.java:96)
at org.testng.TestNG.runSuitesSequentially(TestNG.java:1212)
at org.testng.TestNG.runSuitesLocally(TestNG.java:1134)
at org.testng.TestNG.runSuites(TestNG.java:1063)
at org.testng.TestNG.run(TestNG.java:1031)
at org.testng.remote.AbstractRemoteTestNG.run(AbstractRemoteTestNG.java:115)
at org.testng.remote.RemoteTestNG.initAndRun(RemoteTestNG.java:251)
at org.testng.remote.RemoteTestNG.main(RemoteTestNG.java:77)
]]>
            </full-stacktrace>
          </exception> <!-- java.lang.AssertionError -->
          <reporter-output>
          </reporter-output>
        </test-method> <!-- SUPPORTTICKET -->
        <test-method is-config="true" signature="logout()[pri:0, instance:sample.DASHBOARD_01@942a29c]" started-at="2023-01-03T15:33:15 IST" name="logout" finished-at="2023-01-03T15:33:17 IST" duration-ms="1837" status="PASS">
          <reporter-output>
          </reporter-output>
        </test-method> <!-- logout -->
        <test-method is-config="true" signature="login()[pri:0, instance:sample.DASHBOARD_01@942a29c]" started-at="2023-01-03T15:33:17 IST" name="login" finished-at="2023-01-03T15:33:21 IST" duration-ms="4041" status="PASS">
          <reporter-output>
          </reporter-output>
        </test-method> <!-- login -->
        <test-method signature="SUPPORTTICKET(java.lang.String,java.lang.String)[pri:0, instance:sample.DASHBOARD_01@942a29c]" started-at="2023-01-03T15:33:21 IST" name="SUPPORTTICKET" data-provider="OrgData" finished-at="2023-01-03T15:33:30 IST" duration-ms="8771" status="FAIL">
          <params>
            <param index="0">
              <value>
                <![CDATA[GOOD]]>
              </value>
            </param>
            <param index="1">
              <value>
                <![CDATA[RIGHT]]>
              </value>
            </param>
          </params>
          <exception class="java.lang.AssertionError">
            <message>
              <![CDATA[expected [ New ticket created successfully ] but found [New ticket created successfully]]]>
            </message>
            <full-stacktrace>
              <![CDATA[java.lang.AssertionError: expected [ New ticket created successfully ] but found [New ticket created successfully]
at org.testng.Assert.fail(Assert.java:99)
at org.testng.Assert.failNotEquals(Assert.java:1037)
at org.testng.Assert.assertEqualsImpl(Assert.java:140)
at org.testng.Assert.assertEquals(Assert.java:122)
at org.testng.Assert.assertEquals(Assert.java:629)
at org.testng.Assert.assertEquals(Assert.java:639)
at PAYTMPE_POR.CREATE_NEW_TICKET_PAGE.User_ticketcreatedsucessfully(CREATE_NEW_TICKET_PAGE.java:43)
at sample.DASHBOARD_01.SUPPORTTICKET(DASHBOARD_01.java:41)
at java.base/jdk.internal.reflect.NativeMethodAccessorImpl.invoke0(Native Method)
at java.base/jdk.internal.reflect.NativeMethodAccessorImpl.invoke(NativeMethodAccessorImpl.java:77)
at java.base/jdk.internal.reflect.DelegatingMethodAccessorImpl.invoke(DelegatingMethodAccessorImpl.java:43)
at java.base/java.lang.reflect.Method.invoke(Method.java:568)
at org.testng.internal.MethodInvocationHelper.invokeMethod(MethodInvocationHelper.java:133)
at org.testng.internal.TestInvoker.invokeMethod(TestInvoker.java:598)
at org.testng.internal.TestInvoker.invokeTestMethod(TestInvoker.java:173)
at org.testng.internal.MethodRunner.runInSequence(MethodRunner.java:46)
at org.testng.internal.TestInvoker$MethodInvocationAgent.invoke(TestInvoker.java:824)
at org.testng.internal.TestInvoker.invokeTestMethods(TestInvoker.java:146)
at org.testng.internal.TestMethodWorker.invokeTestMethods(TestMethodWorker.java:146)
at org.testng.internal.TestMethodWorker.run(TestMethodWorker.java:128)
at java.base/java.util.ArrayList.forEach(ArrayList.java:1511)
at org.testng.TestRunner.privateRun(TestRunner.java:794)
at org.testng.TestRunner.run(TestRunner.java:596)
at org.testng.SuiteRunner.runTest(SuiteRunner.java:377)
at org.testng.SuiteRunner.runSequentially(SuiteRunner.java:371)
at org.testng.SuiteRunner.privateRun(SuiteRunner.java:332)
at org.testng.SuiteRunner.run(SuiteRunner.java:276)
at org.testng.SuiteRunnerWorker.runSuite(SuiteRunnerWorker.java:53)
at org.testng.SuiteRunnerWorker.run(SuiteRunnerWorker.java:96)
at org.testng.TestNG.runSuitesSequentially(TestNG.java:1212)
at org.testng.TestNG.runSuitesLocally(TestNG.java:1134)
at org.testng.TestNG.runSuites(TestNG.java:1063)
at org.testng.TestNG.run(TestNG.java:1031)
at org.testng.remote.AbstractRemoteTestNG.run(AbstractRemoteTestNG.java:115)
at org.testng.remote.RemoteTestNG.initAndRun(RemoteTestNG.java:251)
at org.testng.remote.RemoteTestNG.main(RemoteTestNG.java:77)
]]>
            </full-stacktrace>
          </exception> <!-- java.lang.AssertionError -->
          <reporter-output>
          </reporter-output>
        </test-method> <!-- SUPPORTTICKET -->
        <test-method is-config="true" signature="logout()[pri:0, instance:sample.DASHBOARD_01@942a29c]" started-at="2023-01-03T15:33:30 IST" name="logout" finished-at="2023-01-03T15:33:32 IST" duration-ms="1810" status="PASS">
          <reporter-output>
          </reporter-output>
        </test-method> <!-- logout -->
        <test-method is-config="true" signature="login()[pri:0, instance:sample.DASHBOARD_01@942a29c]" started-at="2023-01-03T15:33:32 IST" name="login" finished-at="2023-01-03T15:33:36 IST" duration-ms="4501" status="PASS">
          <reporter-output>
          </reporter-output>
        </test-method> <!-- login -->
        <test-method signature="SUPPORTTICKET(java.lang.String,java.lang.String)[pri:0, instance:sample.DASHBOARD_01@942a29c]" started-at="2023-01-03T15:33:36 IST" name="SUPPORTTICKET" data-provider="OrgData" finished-at="2023-01-03T15:33:46 IST" duration-ms="9721" status="FAIL">
          <params>
            <param index="0">
              <value>
                <![CDATA[FRIDAY]]>
              </value>
            </param>
            <param index="1">
              <value>
                <![CDATA[FRIDAY]]>
              </value>
            </param>
          </params>
          <exception class="java.lang.AssertionError">
            <message>
              <![CDATA[expected [ New ticket created successfully ] but found [New ticket created successfully]]]>
            </message>
            <full-stacktrace>
              <![CDATA[java.lang.AssertionError: expected [ New ticket created successfully ] but found [New ticket created successfully]
at org.testng.Assert.fail(Assert.java:99)
at org.testng.Assert.failNotEquals(Assert.java:1037)
at org.testng.Assert.assertEqualsImpl(Assert.java:140)
at org.testng.Assert.assertEquals(Assert.java:122)
at org.testng.Assert.assertEquals(Assert.java:629)
at org.testng.Assert.assertEquals(Assert.java:639)
at PAYTMPE_POR.CREATE_NEW_TICKET_PAGE.User_ticketcreatedsucessfully(CREATE_NEW_TICKET_PAGE.java:43)
at sample.DASHBOARD_01.SUPPORTTICKET(DASHBOARD_01.java:41)
at java.base/jdk.internal.reflect.NativeMethodAccessorImpl.invoke0(Native Method)
at java.base/jdk.internal.reflect.NativeMethodAccessorImpl.invoke(NativeMethodAccessorImpl.java:77)
at java.base/jdk.internal.reflect.DelegatingMethodAccessorImpl.invoke(DelegatingMethodAccessorImpl.java:43)
at java.base/java.lang.reflect.Method.invoke(Method.java:568)
at org.testng.internal.MethodInvocationHelper.invokeMethod(MethodInvocationHelper.java:133)
at org.testng.internal.TestInvoker.invokeMethod(TestInvoker.java:598)
at org.testng.internal.TestInvoker.invokeTestMethod(TestInvoker.java:173)
at org.testng.internal.MethodRunner.runInSequence(MethodRunner.java:46)
at org.testng.internal.TestInvoker$MethodInvocationAgent.invoke(TestInvoker.java:824)
at org.testng.internal.TestInvoker.invokeTestMethods(TestInvoker.java:146)
at org.testng.internal.TestMethodWorker.invokeTestMethods(TestMethodWorker.java:146)
at org.testng.internal.TestMethodWorker.run(TestMethodWorker.java:128)
at java.base/java.util.ArrayList.forEach(ArrayList.java:1511)
at org.testng.TestRunner.privateRun(TestRunner.java:794)
at org.testng.TestRunner.run(TestRunner.java:596)
at org.testng.SuiteRunner.runTest(SuiteRunner.java:377)
at org.testng.SuiteRunner.runSequentially(SuiteRunner.java:371)
at org.testng.SuiteRunner.privateRun(SuiteRunner.java:332)
at org.testng.SuiteRunner.run(SuiteRunner.java:276)
at org.testng.SuiteRunnerWorker.runSuite(SuiteRunnerWorker.java:53)
at org.testng.SuiteRunnerWorker.run(SuiteRunnerWorker.java:96)
at org.testng.TestNG.runSuitesSequentially(TestNG.java:1212)
at org.testng.TestNG.runSuitesLocally(TestNG.java:1134)
at org.testng.TestNG.runSuites(TestNG.java:1063)
at org.testng.TestNG.run(TestNG.java:1031)
at org.testng.remote.AbstractRemoteTestNG.run(AbstractRemoteTestNG.java:115)
at org.testng.remote.RemoteTestNG.initAndRun(RemoteTestNG.java:251)
at org.testng.remote.RemoteTestNG.main(RemoteTestNG.java:77)
]]>
            </full-stacktrace>
          </exception> <!-- java.lang.AssertionError -->
          <reporter-output>
          </reporter-output>
        </test-method> <!-- SUPPORTTICKET -->
        <test-method is-config="true" signature="logout()[pri:0, instance:sample.DASHBOARD_01@942a29c]" started-at="2023-01-03T15:33:46 IST" name="logout" finished-at="2023-01-03T15:33:48 IST" duration-ms="2066" status="PASS">
          <reporter-output>
          </reporter-output>
        </test-method> <!-- logout -->
        <test-method is-config="true" signature="login()[pri:0, instance:sample.DASHBOARD_01@942a29c]" started-at="2023-01-03T15:33:48 IST" name="login" finished-at="2023-01-03T15:33:53 IST" duration-ms="5376" status="PASS">
          <reporter-output>
          </reporter-output>
        </test-method> <!-- login -->
        <test-method signature="SUPPORTTICKET(java.lang.String,java.lang.String)[pri:0, instance:sample.DASHBOARD_01@942a29c]" started-at="2023-01-03T15:33:53 IST" name="SUPPORTTICKET" data-provider="OrgData" finished-at="2023-01-03T15:34:03 IST" duration-ms="9789" status="FAIL">
          <params>
            <param index="0">
              <value>
                <![CDATA[SATURDAY]]>
              </value>
            </param>
            <param index="1">
              <value>
                <![CDATA[SATURDAY]]>
              </value>
            </param>
          </params>
          <exception class="java.lang.AssertionError">
            <message>
              <![CDATA[expected [ New ticket created successfully ] but found [New ticket created successfully]]]>
            </message>
            <full-stacktrace>
              <![CDATA[java.lang.AssertionError: expected [ New ticket created successfully ] but found [New ticket created successfully]
at org.testng.Assert.fail(Assert.java:99)
at org.testng.Assert.failNotEquals(Assert.java:1037)
at org.testng.Assert.assertEqualsImpl(Assert.java:140)
at org.testng.Assert.assertEquals(Assert.java:122)
at org.testng.Assert.assertEquals(Assert.java:629)
at org.testng.Assert.assertEquals(Assert.java:639)
at PAYTMPE_POR.CREATE_NEW_TICKET_PAGE.User_ticketcreatedsucessfully(CREATE_NEW_TICKET_PAGE.java:43)
at sample.DASHBOARD_01.SUPPORTTICKET(DASHBOARD_01.java:41)
at java.base/jdk.internal.reflect.NativeMethodAccessorImpl.invoke0(Native Method)
at java.base/jdk.internal.reflect.NativeMethodAccessorImpl.invoke(NativeMethodAccessorImpl.java:77)
at java.base/jdk.internal.reflect.DelegatingMethodAccessorImpl.invoke(DelegatingMethodAccessorImpl.java:43)
at java.base/java.lang.reflect.Method.invoke(Method.java:568)
at org.testng.internal.MethodInvocationHelper.invokeMethod(MethodInvocationHelper.java:133)
at org.testng.internal.TestInvoker.invokeMethod(TestInvoker.java:598)
at org.testng.internal.TestInvoker.invokeTestMethod(TestInvoker.java:173)
at org.testng.internal.MethodRunner.runInSequence(MethodRunner.java:46)
at org.testng.internal.TestInvoker$MethodInvocationAgent.invoke(TestInvoker.java:824)
at org.testng.internal.TestInvoker.invokeTestMethods(TestInvoker.java:146)
at org.testng.internal.TestMethodWorker.invokeTestMethods(TestMethodWorker.java:146)
at org.testng.internal.TestMethodWorker.run(TestMethodWorker.java:128)
at java.base/java.util.ArrayList.forEach(ArrayList.java:1511)
at org.testng.TestRunner.privateRun(TestRunner.java:794)
at org.testng.TestRunner.run(TestRunner.java:596)
at org.testng.SuiteRunner.runTest(SuiteRunner.java:377)
at org.testng.SuiteRunner.runSequentially(SuiteRunner.java:371)
at org.testng.SuiteRunner.privateRun(SuiteRunner.java:332)
at org.testng.SuiteRunner.run(SuiteRunner.java:276)
at org.testng.SuiteRunnerWorker.runSuite(SuiteRunnerWorker.java:53)
at org.testng.SuiteRunnerWorker.run(SuiteRunnerWorker.java:96)
at org.testng.TestNG.runSuitesSequentially(TestNG.java:1212)
at org.testng.TestNG.runSuitesLocally(TestNG.java:1134)
at org.testng.TestNG.runSuites(TestNG.java:1063)
at org.testng.TestNG.run(TestNG.java:1031)
at org.testng.remote.AbstractRemoteTestNG.run(AbstractRemoteTestNG.java:115)
at org.testng.remote.RemoteTestNG.initAndRun(RemoteTestNG.java:251)
at org.testng.remote.RemoteTestNG.main(RemoteTestNG.java:77)
]]>
            </full-stacktrace>
          </exception> <!-- java.lang.AssertionError -->
          <reporter-output>
          </reporter-output>
        </test-method> <!-- SUPPORTTICKET -->
        <test-method is-config="true" signature="logout()[pri:0, instance:sample.DASHBOARD_01@942a29c]" started-at="2023-01-03T15:34:03 IST" name="logout" finished-at="2023-01-03T15:34:06 IST" duration-ms="2145" status="PASS">
          <reporter-output>
          </reporter-output>
        </test-method> <!-- logout -->
        <test-method is-config="true" signature="login()[pri:0, instance:sample.DASHBOARD_01@942a29c]" started-at="2023-01-03T15:34:06 IST" name="login" finished-at="2023-01-03T15:34:10 IST" duration-ms="4705" status="PASS">
          <reporter-output>
          </reporter-output>
        </test-method> <!-- login -->
        <test-method signature="SUPPORTTICKET(java.lang.String,java.lang.String)[pri:0, instance:sample.DASHBOARD_01@942a29c]" started-at="2023-01-03T15:34:10 IST" name="SUPPORTTICKET" data-provider="OrgData" finished-at="2023-01-03T15:34:20 IST" duration-ms="9584" status="FAIL">
          <params>
            <param index="0">
              <value>
                <![CDATA[SUNDAY]]>
              </value>
            </param>
            <param index="1">
              <value>
                <![CDATA[SUNDAY]]>
              </value>
            </param>
          </params>
          <exception class="java.lang.AssertionError">
            <message>
              <![CDATA[expected [ New ticket created successfully ] but found [New ticket created successfully]]]>
            </message>
            <full-stacktrace>
              <![CDATA[java.lang.AssertionError: expected [ New ticket created successfully ] but found [New ticket created successfully]
at org.testng.Assert.fail(Assert.java:99)
at org.testng.Assert.failNotEquals(Assert.java:1037)
at org.testng.Assert.assertEqualsImpl(Assert.java:140)
at org.testng.Assert.assertEquals(Assert.java:122)
at org.testng.Assert.assertEquals(Assert.java:629)
at org.testng.Assert.assertEquals(Assert.java:639)
at PAYTMPE_POR.CREATE_NEW_TICKET_PAGE.User_ticketcreatedsucessfully(CREATE_NEW_TICKET_PAGE.java:43)
at sample.DASHBOARD_01.SUPPORTTICKET(DASHBOARD_01.java:41)
at java.base/jdk.internal.reflect.NativeMethodAccessorImpl.invoke0(Native Method)
at java.base/jdk.internal.reflect.NativeMethodAccessorImpl.invoke(NativeMethodAccessorImpl.java:77)
at java.base/jdk.internal.reflect.DelegatingMethodAccessorImpl.invoke(DelegatingMethodAccessorImpl.java:43)
at java.base/java.lang.reflect.Method.invoke(Method.java:568)
at org.testng.internal.MethodInvocationHelper.invokeMethod(MethodInvocationHelper.java:133)
at org.testng.internal.TestInvoker.invokeMethod(TestInvoker.java:598)
at org.testng.internal.TestInvoker.invokeTestMethod(TestInvoker.java:173)
at org.testng.internal.MethodRunner.runInSequence(MethodRunner.java:46)
at org.testng.internal.TestInvoker$MethodInvocationAgent.invoke(TestInvoker.java:824)
at org.testng.internal.TestInvoker.invokeTestMethods(TestInvoker.java:146)
at org.testng.internal.TestMethodWorker.invokeTestMethods(TestMethodWorker.java:146)
at org.testng.internal.TestMethodWorker.run(TestMethodWorker.java:128)
at java.base/java.util.ArrayList.forEach(ArrayList.java:1511)
at org.testng.TestRunner.privateRun(TestRunner.java:794)
at org.testng.TestRunner.run(TestRunner.java:596)
at org.testng.SuiteRunner.runTest(SuiteRunner.java:377)
at org.testng.SuiteRunner.runSequentially(SuiteRunner.java:371)
at org.testng.SuiteRunner.privateRun(SuiteRunner.java:332)
at org.testng.SuiteRunner.run(SuiteRunner.java:276)
at org.testng.SuiteRunnerWorker.runSuite(SuiteRunnerWorker.java:53)
at org.testng.SuiteRunnerWorker.run(SuiteRunnerWorker.java:96)
at org.testng.TestNG.runSuitesSequentially(TestNG.java:1212)
at org.testng.TestNG.runSuitesLocally(TestNG.java:1134)
at org.testng.TestNG.runSuites(TestNG.java:1063)
at org.testng.TestNG.run(TestNG.java:1031)
at org.testng.remote.AbstractRemoteTestNG.run(AbstractRemoteTestNG.java:115)
at org.testng.remote.RemoteTestNG.initAndRun(RemoteTestNG.java:251)
at org.testng.remote.RemoteTestNG.main(RemoteTestNG.java:77)
]]>
            </full-stacktrace>
          </exception> <!-- java.lang.AssertionError -->
          <reporter-output>
          </reporter-output>
        </test-method> <!-- SUPPORTTICKET -->
        <test-method is-config="true" signature="logout()[pri:0, instance:sample.DASHBOARD_01@942a29c]" started-at="2023-01-03T15:34:20 IST" name="logout" finished-at="2023-01-03T15:34:22 IST" duration-ms="2038" status="PASS">
          <reporter-output>
          </reporter-output>
        </test-method> <!-- logout -->
        <test-method is-config="true" signature="login()[pri:0, instance:sample.DASHBOARD_01@942a29c]" started-at="2023-01-03T15:34:22 IST" name="login" finished-at="2023-01-03T15:34:27 IST" duration-ms="4553" status="PASS">
          <reporter-output>
          </reporter-output>
        </test-method> <!-- login -->
        <test-method signature="SUPPORTTICKET(java.lang.String,java.lang.String)[pri:0, instance:sample.DASHBOARD_01@942a29c]" started-at="2023-01-03T15:34:27 IST" name="SUPPORTTICKET" data-provider="OrgData" finished-at="2023-01-03T15:34:38 IST" duration-ms="10869" status="FAIL">
          <params>
            <param index="0">
              <value>
                <![CDATA[MONDAY]]>
              </value>
            </param>
            <param index="1">
              <value>
                <![CDATA[MONDAY]]>
              </value>
            </param>
          </params>
          <exception class="java.lang.AssertionError">
            <message>
              <![CDATA[expected [ New ticket created successfully ] but found [New ticket created successfully]]]>
            </message>
            <full-stacktrace>
              <![CDATA[java.lang.AssertionError: expected [ New ticket created successfully ] but found [New ticket created successfully]
at org.testng.Assert.fail(Assert.java:99)
at org.testng.Assert.failNotEquals(Assert.java:1037)
at org.testng.Assert.assertEqualsImpl(Assert.java:140)
at org.testng.Assert.assertEquals(Assert.java:122)
at org.testng.Assert.assertEquals(Assert.java:629)
at org.testng.Assert.assertEquals(Assert.java:639)
at PAYTMPE_POR.CREATE_NEW_TICKET_PAGE.User_ticketcreatedsucessfully(CREATE_NEW_TICKET_PAGE.java:43)
at sample.DASHBOARD_01.SUPPORTTICKET(DASHBOARD_01.java:41)
at java.base/jdk.internal.reflect.NativeMethodAccessorImpl.invoke0(Native Method)
at java.base/jdk.internal.reflect.NativeMethodAccessorImpl.invoke(NativeMethodAccessorImpl.java:77)
at java.base/jdk.internal.reflect.DelegatingMethodAccessorImpl.invoke(DelegatingMethodAccessorImpl.java:43)
at java.base/java.lang.reflect.Method.invoke(Method.java:568)
at org.testng.internal.MethodInvocationHelper.invokeMethod(MethodInvocationHelper.java:133)
at org.testng.internal.TestInvoker.invokeMethod(TestInvoker.java:598)
at org.testng.internal.TestInvoker.invokeTestMethod(TestInvoker.java:173)
at org.testng.internal.MethodRunner.runInSequence(MethodRunner.java:46)
at org.testng.internal.TestInvoker$MethodInvocationAgent.invoke(TestInvoker.java:824)
at org.testng.internal.TestInvoker.invokeTestMethods(TestInvoker.java:146)
at org.testng.internal.TestMethodWorker.invokeTestMethods(TestMethodWorker.java:146)
at org.testng.internal.TestMethodWorker.run(TestMethodWorker.java:128)
at java.base/java.util.ArrayList.forEach(ArrayList.java:1511)
at org.testng.TestRunner.privateRun(TestRunner.java:794)
at org.testng.TestRunner.run(TestRunner.java:596)
at org.testng.SuiteRunner.runTest(SuiteRunner.java:377)
at org.testng.SuiteRunner.runSequentially(SuiteRunner.java:371)
at org.testng.SuiteRunner.privateRun(SuiteRunner.java:332)
at org.testng.SuiteRunner.run(SuiteRunner.java:276)
at org.testng.SuiteRunnerWorker.runSuite(SuiteRunnerWorker.java:53)
at org.testng.SuiteRunnerWorker.run(SuiteRunnerWorker.java:96)
at org.testng.TestNG.runSuitesSequentially(TestNG.java:1212)
at org.testng.TestNG.runSuitesLocally(TestNG.java:1134)
at org.testng.TestNG.runSuites(TestNG.java:1063)
at org.testng.TestNG.run(TestNG.java:1031)
at org.testng.remote.AbstractRemoteTestNG.run(AbstractRemoteTestNG.java:115)
at org.testng.remote.RemoteTestNG.initAndRun(RemoteTestNG.java:251)
at org.testng.remote.RemoteTestNG.main(RemoteTestNG.java:77)
]]>
            </full-stacktrace>
          </exception> <!-- java.lang.AssertionError -->
          <reporter-output>
          </reporter-output>
        </test-method> <!-- SUPPORTTICKET -->
        <test-method is-config="true" signature="logout()[pri:0, instance:sample.DASHBOARD_01@942a29c]" started-at="2023-01-03T15:34:38 IST" name="logout" finished-at="2023-01-03T15:34:40 IST" duration-ms="2010" status="PASS">
          <reporter-output>
          </reporter-output>
        </test-method> <!-- logout -->
        <test-method is-config="true" signature="login()[pri:0, instance:sample.DASHBOARD_01@942a29c]" started-at="2023-01-03T15:34:40 IST" name="login" finished-at="2023-01-03T15:34:45 IST" duration-ms="5181" status="PASS">
          <reporter-output>
          </reporter-output>
        </test-method> <!-- login -->
        <test-method signature="SUPPORTTICKET(java.lang.String,java.lang.String)[pri:0, instance:sample.DASHBOARD_01@942a29c]" started-at="2023-01-03T15:34:45 IST" name="SUPPORTTICKET" data-provider="OrgData" finished-at="2023-01-03T15:34:54 IST" duration-ms="8662" status="FAIL">
          <params>
            <param index="0">
              <value>
                <![CDATA[TUESDAY]]>
              </value>
            </param>
            <param index="1">
              <value>
                <![CDATA[TUESDAY]]>
              </value>
            </param>
          </params>
          <exception class="java.lang.AssertionError">
            <message>
              <![CDATA[expected [ New ticket created successfully ] but found [New ticket created successfully]]]>
            </message>
            <full-stacktrace>
              <![CDATA[java.lang.AssertionError: expected [ New ticket created successfully ] but found [New ticket created successfully]
at org.testng.Assert.fail(Assert.java:99)
at org.testng.Assert.failNotEquals(Assert.java:1037)
at org.testng.Assert.assertEqualsImpl(Assert.java:140)
at org.testng.Assert.assertEquals(Assert.java:122)
at org.testng.Assert.assertEquals(Assert.java:629)
at org.testng.Assert.assertEquals(Assert.java:639)
at PAYTMPE_POR.CREATE_NEW_TICKET_PAGE.User_ticketcreatedsucessfully(CREATE_NEW_TICKET_PAGE.java:43)
at sample.DASHBOARD_01.SUPPORTTICKET(DASHBOARD_01.java:41)
at java.base/jdk.internal.reflect.NativeMethodAccessorImpl.invoke0(Native Method)
at java.base/jdk.internal.reflect.NativeMethodAccessorImpl.invoke(NativeMethodAccessorImpl.java:77)
at java.base/jdk.internal.reflect.DelegatingMethodAccessorImpl.invoke(DelegatingMethodAccessorImpl.java:43)
at java.base/java.lang.reflect.Method.invoke(Method.java:568)
at org.testng.internal.MethodInvocationHelper.invokeMethod(MethodInvocationHelper.java:133)
at org.testng.internal.TestInvoker.invokeMethod(TestInvoker.java:598)
at org.testng.internal.TestInvoker.invokeTestMethod(TestInvoker.java:173)
at org.testng.internal.MethodRunner.runInSequence(MethodRunner.java:46)
at org.testng.internal.TestInvoker$MethodInvocationAgent.invoke(TestInvoker.java:824)
at org.testng.internal.TestInvoker.invokeTestMethods(TestInvoker.java:146)
at org.testng.internal.TestMethodWorker.invokeTestMethods(TestMethodWorker.java:146)
at org.testng.internal.TestMethodWorker.run(TestMethodWorker.java:128)
at java.base/java.util.ArrayList.forEach(ArrayList.java:1511)
at org.testng.TestRunner.privateRun(TestRunner.java:794)
at org.testng.TestRunner.run(TestRunner.java:596)
at org.testng.SuiteRunner.runTest(SuiteRunner.java:377)
at org.testng.SuiteRunner.runSequentially(SuiteRunner.java:371)
at org.testng.SuiteRunner.privateRun(SuiteRunner.java:332)
at org.testng.SuiteRunner.run(SuiteRunner.java:276)
at org.testng.SuiteRunnerWorker.runSuite(SuiteRunnerWorker.java:53)
at org.testng.SuiteRunnerWorker.run(SuiteRunnerWorker.java:96)
at org.testng.TestNG.runSuitesSequentially(TestNG.java:1212)
at org.testng.TestNG.runSuitesLocally(TestNG.java:1134)
at org.testng.TestNG.runSuites(TestNG.java:1063)
at org.testng.TestNG.run(TestNG.java:1031)
at org.testng.remote.AbstractRemoteTestNG.run(AbstractRemoteTestNG.java:115)
at org.testng.remote.RemoteTestNG.initAndRun(RemoteTestNG.java:251)
at org.testng.remote.RemoteTestNG.main(RemoteTestNG.java:77)
]]>
            </full-stacktrace>
          </exception> <!-- java.lang.AssertionError -->
          <reporter-output>
          </reporter-output>
        </test-method> <!-- SUPPORTTICKET -->
        <test-method is-config="true" signature="logout()[pri:0, instance:sample.DASHBOARD_01@942a29c]" started-at="2023-01-03T15:34:54 IST" name="logout" finished-at="2023-01-03T15:34:56 IST" duration-ms="2063" status="PASS">
          <reporter-output>
          </reporter-output>
        </test-method> <!-- logout -->
        <test-method is-config="true" signature="login()[pri:0, instance:sample.DASHBOARD_01@942a29c]" started-at="2023-01-03T15:34:56 IST" name="login" finished-at="2023-01-03T15:35:03 IST" duration-ms="7120" status="PASS">
          <reporter-output>
          </reporter-output>
        </test-method> <!-- login -->
        <test-method signature="SUPPORTTICKET(java.lang.String,java.lang.String)[pri:0, instance:sample.DASHBOARD_01@942a29c]" started-at="2023-01-03T15:35:03 IST" name="SUPPORTTICKET" data-provider="OrgData" finished-at="2023-01-03T15:35:14 IST" duration-ms="10674" status="FAIL">
          <params>
            <param index="0">
              <value>
                <![CDATA[WEDNESDAY]]>
              </value>
            </param>
            <param index="1">
              <value>
                <![CDATA[WEDNESDAY]]>
              </value>
            </param>
          </params>
          <exception class="java.lang.AssertionError">
            <message>
              <![CDATA[expected [ New ticket created successfully ] but found [New ticket created successfully]]]>
            </message>
            <full-stacktrace>
              <![CDATA[java.lang.AssertionError: expected [ New ticket created successfully ] but found [New ticket created successfully]
at org.testng.Assert.fail(Assert.java:99)
at org.testng.Assert.failNotEquals(Assert.java:1037)
at org.testng.Assert.assertEqualsImpl(Assert.java:140)
at org.testng.Assert.assertEquals(Assert.java:122)
at org.testng.Assert.assertEquals(Assert.java:629)
at org.testng.Assert.assertEquals(Assert.java:639)
at PAYTMPE_POR.CREATE_NEW_TICKET_PAGE.User_ticketcreatedsucessfully(CREATE_NEW_TICKET_PAGE.java:43)
at sample.DASHBOARD_01.SUPPORTTICKET(DASHBOARD_01.java:41)
at java.base/jdk.internal.reflect.NativeMethodAccessorImpl.invoke0(Native Method)
at java.base/jdk.internal.reflect.NativeMethodAccessorImpl.invoke(NativeMethodAccessorImpl.java:77)
at java.base/jdk.internal.reflect.DelegatingMethodAccessorImpl.invoke(DelegatingMethodAccessorImpl.java:43)
at java.base/java.lang.reflect.Method.invoke(Method.java:568)
at org.testng.internal.MethodInvocationHelper.invokeMethod(MethodInvocationHelper.java:133)
at org.testng.internal.TestInvoker.invokeMethod(TestInvoker.java:598)
at org.testng.internal.TestInvoker.invokeTestMethod(TestInvoker.java:173)
at org.testng.internal.MethodRunner.runInSequence(MethodRunner.java:46)
at org.testng.internal.TestInvoker$MethodInvocationAgent.invoke(TestInvoker.java:824)
at org.testng.internal.TestInvoker.invokeTestMethods(TestInvoker.java:146)
at org.testng.internal.TestMethodWorker.invokeTestMethods(TestMethodWorker.java:146)
at org.testng.internal.TestMethodWorker.run(TestMethodWorker.java:128)
at java.base/java.util.ArrayList.forEach(ArrayList.java:1511)
at org.testng.TestRunner.privateRun(TestRunner.java:794)
at org.testng.TestRunner.run(TestRunner.java:596)
at org.testng.SuiteRunner.runTest(SuiteRunner.java:377)
at org.testng.SuiteRunner.runSequentially(SuiteRunner.java:371)
at org.testng.SuiteRunner.privateRun(SuiteRunner.java:332)
at org.testng.SuiteRunner.run(SuiteRunner.java:276)
at org.testng.SuiteRunnerWorker.runSuite(SuiteRunnerWorker.java:53)
at org.testng.SuiteRunnerWorker.run(SuiteRunnerWorker.java:96)
at org.testng.TestNG.runSuitesSequentially(TestNG.java:1212)
at org.testng.TestNG.runSuitesLocally(TestNG.java:1134)
at org.testng.TestNG.runSuites(TestNG.java:1063)
at org.testng.TestNG.run(TestNG.java:1031)
at org.testng.remote.AbstractRemoteTestNG.run(AbstractRemoteTestNG.java:115)
at org.testng.remote.RemoteTestNG.initAndRun(RemoteTestNG.java:251)
at org.testng.remote.RemoteTestNG.main(RemoteTestNG.java:77)
]]>
            </full-stacktrace>
          </exception> <!-- java.lang.AssertionError -->
          <reporter-output>
          </reporter-output>
        </test-method> <!-- SUPPORTTICKET -->
        <test-method is-config="true" signature="logout()[pri:0, instance:sample.DASHBOARD_01@942a29c]" started-at="2023-01-03T15:35:14 IST" name="logout" finished-at="2023-01-03T15:35:16 IST" duration-ms="1649" status="PASS">
          <reporter-output>
          </reporter-output>
        </test-method> <!-- logout -->
        <test-method is-config="true" signature="Teardown()[pri:0, instance:sample.DASHBOARD_01@942a29c]" started-at="2023-01-03T15:35:16 IST" name="Teardown" finished-at="2023-01-03T15:35:16 IST" duration-ms="188" status="PASS">
          <reporter-output>
          </reporter-output>
        </test-method> <!-- Teardown -->
      </class> <!-- sample.DASHBOARD_01 -->
    </test> <!-- Test -->
  </suite> <!-- Suite -->
</testng-results>
